Workbook

Sheet PL2_Horarios
A1: No | B1: COD_CATE | C1: COD_ASIG | D1: ASIGNATURA | E1: SECCION | F1: HORARIO | G1: DURACION | H1: DIAS | I1: MODALIDAD | J1: TIT | K1: DOCENTE | L1: ID_DOCENTE
A2: 1 | B2: DES | C2: ADCC-I | D2: Administración De Centros De Cómputo | E2: 01 | F2: 20:30-22:00 | G2: 90 min | H2: Lu-Mi | I2: EN LÍNEA | J2: =IFERROR(VLOOKUP(K2,Docentes_Lista!$A$2:$C$212,2,FALSE),"") -> 0 | L2: =IFERROR(VLOOKUP(K2,Docentes_Lista!$A$2:$C$212,3,FALSE),"") -> 0
A3: 2 | B3: DES | C3: ADCC-I | D3: Administración De Centros De Cómputo | E3: 01 | F3: 06:30-08:00 | G3: 90 min | H3: Ju-Ma | I3: EN LÍNEA | J3: =IFERROR(VLOOKUP(K3,Docentes_Lista!$A$2:$C$212,2,FALSE),"") -> 0 | L3: =IFERROR(VLOOKUP(K3,Docentes_Lista!$A$2:$C$212,3,FALSE),"") -> 0
A4: 3 | B4: DES | C4: ADCC-V | D4: Administración De Centros De Cómputo | E4: 01 | F4: 00:00-23:59 | H4: Do-Ju-Lu-Ma-Mi-Sa-Vi | I4: AULA VIRTUAL | J4: =IFERROR(VLOOKUP(K4,Docentes_Lista!$A$2:$C$212,2,FALSE),"") -> 0 | L4: =IFERROR(VLOOKUP(K4,Docentes_Lista!$A$2:$C$212,3,FALSE),"") -> 0
A5: 4 | B5: PRO | C5: ALG1-E | D5: Algoritmos I | E5: 01 | F5: 09:45-11:15 | G5: 90 min | H5: Lu-Vi | I5: PRESENCIAL | J5: =IFERROR(VLOOKUP(K5,Docentes_Lista!$A$2:$C$212,2,FALSE),"") -> 0 | L5: =IFERROR(VLOOKUP(K5,Docentes_Lista!$A$2:$C$212,3,FALSE),"") -> 0
A6: 5 | B6: PRO | C6: ALG1-E | D6: Algoritmos I | E6: 02 | F6: 18:40-20:10 | G6: 90 min | H6: Lu-Mi | I6: PRESENCIAL | J6: =IFERROR(VLOOKUP(K6,Docentes_Lista!$A$2:$C$212,2,FALSE),"") -> 0 | L6: =IFERROR(VLOOKUP(K6,Docentes_Lista!$A$2:$C$212,3,FALSE),"") -> 0
A7: 6 | B7: PRO | C7: ALG1-V | D7: Algoritmos I | E7: 03 | F7: 00:00-23:59 | H7: Do-Ju-Lu-Ma-Mi-Sa-Vi | I7: AULA VIRTUAL | J7: =IFERROR(VLOOKUP(K7,Docentes_Lista!$A$2:$C$212,2,FALSE),"") -> 0 | L7: =IFERROR(VLOOKUP(K7,Docentes_Lista!$A$2:$C$212,3,FALSE),"") -> 0
A8: 7 | B8: RED | C8: ARTE-V | D8: Administración De Recursos Tecnológicos (virtual) | E8: 01 | F8: 00:00-23:59 | H8: Do-Ju-Lu-Ma-Mi-Sa-Vi | I8: AULA VIRTUAL | J8: =IFERROR(VLOOKUP(K8,Docentes_Lista!$A$2:$C$212,2,FALSE),"") -> 0 | L8: =IFERROR(VLOOKUP(K8,Docentes_Lista!$A$2:$C$212,3,FALSE),"") -> 0
A9: 8 | B9: DES | C9: AUDS-V | D9: Auditoría De Sistemas | E9: 01 | F9: 00:00-23:59 | H9: Do-Ju-Lu-Ma-Mi-Sa-Vi | I9: AULA VIRTUAL | J9: =IFERROR(VLOOKUP(K9,Docentes_Lista!$A$2:$C$212,2,FALSE),"") -> 0 | L9: =IFERROR(VLOOKUP(K9,Docentes_Lista!$A$2:$C$212,3,FALSE),"") -> 0
A10: 9 | B10: DES | C10: BAS1-I | D10: Bases De Datos I | E10: 01 | F10: 08:00-09:30 | G10: 90 min | H10: Lu-Vi | I10: PRESENCIAL | J10: =IFERROR(VLOOKUP(K10,Docentes_Lista!$A$2:$C$212,2,FALSE),"") -> 0 | L10: =IFERROR(VLOOKUP(K10,Docentes_Lista!$A$2:$C$212,3,FALSE),"") -> 0
A11: 10 | B11: DES | C11: BAS1-I | D11: Bases De Datos I | E11: 03 | F11: 18:40-20:10 | G11: 90 min | H11: Lu-Mi | I11: PRESENCIAL | J11: =IFERROR(VLOOKUP(K11,Docentes_Lista!$A$2:$C$212,2,FALSE),"") -> 0 | L11: =IFERROR(VLOOKUP(K11,Docentes_Lista!$A$2:$C$212,3,FALSE),"") -> 0
A12: 11 | B12: DES | C12: BAS1-I | D12: Bases De Datos I | E12: 02 | F12: 17:00-18:30 | G12: 90 min | H12: Ju-Ma | I12: PRESENCIAL | J12: =IFERROR(VLOOKUP(K12,Docentes_Lista!$A$2:$C$212,2,FALSE),"") -> 0 | L12: =IFERROR(VLOOKUP(K12,Docentes_Lista!$A$2:$C$212,3,FALSE),"") -> 0
A13: 12 | B13: DES | C13: BAS1-I | D13: Bases De Datos I | E13: 04 | F13: 07:00-10:00 | G13: 180 min | H13: Do | I13: PRESENCIAL | J13: =IFERROR(VLOOKUP(K13,Docentes_Lista!$A$2:$C$212,2,FALSE),"") -> 0 | L13: =IFERROR(VLOOKUP(K13,Docentes_Lista!$A$2:$C$212,3,FALSE),"") -> 0
A14: 13 | B14: DES | C14: BAS1-V | D14: Base De Datos I | E14: 01 | F14: 00:00-23:59 | H14: Do-Ju-Lu-Ma-Mi-Sa-Vi | I14: AULA VIRTUAL | J14: =IFERROR(VLOOKUP(K14,Docentes_Lista!$A$2:$C$212,2,FALSE),"") -> 0 | L14: =IFERROR(VLOOKUP(K14,Docentes_Lista!$A$2:$C$212,3,FALSE),"") -> 0
A15: 14 | B15: DES | C15: BAS1-V | D15: Base De Datos I | E15: 02 | F15: 00:00-23:59 | H15: Do-Ju-Lu-Ma-Mi-Sa-Vi | I15: AULA VIRTUAL | J15: =IFERROR(VLOOKUP(K15,Docentes_Lista!$A$2:$C$212,2,FALSE),"") -> 0 | L15: =IFERROR(VLOOKUP(K15,Docentes_Lista!$A$2:$C$212,3,FALSE),"") -> 0
A16: 15 | B16: DES | C16: BAS2-I | D16: Base De Datos II | E16: 03 | F16: 18:40-20:10 | G16: 90 min | H16: Lu-Mi | I16: EN LÍNEA | J16: =IFERROR(VLOOKUP(K16,Docentes_Lista!$A$2:$C$212,2,FALSE),"") -> 0 | L16: =IFERROR(VLOOKUP(K16,Docentes_Lista!$A$2:$C$212,3,FALSE),"") -> 0
A17: 16 | B17: DES | C17: BAS2-I | D17: Base De Datos II | E17: 04 | F17: 20:30-22:00 | G17: 90 min | H17: Lu-Mi | I17: EN LÍNEA | J17: =IFERROR(VLOOKUP(K17,Docentes_Lista!$A$2:$C$212,2,FALSE),"") -> 0 | L17: =IFERROR(VLOOKUP(K17,Docentes_Lista!$A$2:$C$212,3,FALSE),"") -> 0
A18: 17 | B18: DES | C18: BAS2-I | D18: Base De Datos II | E18: 02 | F18: 09:45-11:15 | G18: 90 min | H18: Ju-Ma | I18: EN LÍNEA | J18: =IFERROR(VLOOKUP(K18,Docentes_Lista!$A$2:$C$212,2,FALSE),"") -> 0 | L18: =IFERROR(VLOOKUP(K18,Docentes_Lista!$A$2:$C$212,3,FALSE),"") -> 0
A19: 18 | B19: DES | C19: BAS2-I | D19: Base De Datos II | E19: 01 | F19: 06:30-08:00 | G19: 90 min | H19: Mi-Sa | I19: EN LÍNEA | J19: =IFERROR(VLOOKUP(K19,Docentes_Lista!$A$2:$C$212,2,FALSE),"") -> 0 | L19: =IFERROR(VLOOKUP(K19,Docentes_Lista!$A$2:$C$212,3,FALSE),"") -> 0
A20: 19 | B20: DES | C20: BAS2-V | D20: Base De Datos II | E20: 01 | F20: 00:00-23:59 | H20: Do-Ju-Lu-Ma-Mi-Sa-Vi | I20: AULA VIRTUAL | J20: =IFERROR(VLOOKUP(K20,Docentes_Lista!$A$2:$C$212,2,FALSE),"") -> 0 | L20: =IFERROR(VLOOKUP(K20,Docentes_Lista!$A$2:$C$212,3,FALSE),"") -> 0
A21: 20 | B21: ELE | C21: CIDI-V | D21: Sistemas Digitales (virtual) | E21: 01 | F21: 00:00-23:59 | H21: Do-Ju-Lu-Ma-Mi-Sa-Vi | I21: AULA VIRTUAL | J21: =IFERROR(VLOOKUP(K21,Docentes_Lista!$A$2:$C$212,2,FALSE),"") -> 0 | L21: =IFERROR(VLOOKUP(K21,Docentes_Lista!$A$2:$C$212,3,FALSE),"") -> 0
A22: 21 | B22: DES | C22: DPWEB-V | D22: Desarrollo De La Plataforma Web | E22: 01 | F22: 00:00-23:59 | H22: Do-Ju-Lu-Ma-Mi-Sa-Vi | I22: AULA VIRTUAL | J22: =IFERROR(VLOOKUP(K22,Docentes_Lista!$A$2:$C$212,2,FALSE),"") -> 0 | L22: =IFERROR(VLOOKUP(K22,Docentes_Lista!$A$2:$C$212,3,FALSE),"") -> 0
A23: 22 | B23: DES | C23: DPWEB-V | D23: Desarrollo De La Plataforma Web | E23: 02 | F23: 00:00-23:59 | H23: Do-Ju-Lu-Ma-Mi-Sa-Vi | I23: AULA VIRTUAL | J23: =IFERROR(VLOOKUP(K23,Docentes_Lista!$A$2:$C$212,2,FALSE),"") -> 0 | L23: =IFERROR(VLOOKUP(K23,Docentes_Lista!$A$2:$C$212,3,FALSE),"") -> 0
A24: 23 | B24: ELE | C24: ELE1-V | D24: Electrónica (virtual) | E24: 01 | F24: 00:00-23:59 | H24: Do-Ju-Lu-Ma-Mi-Sa-Vi | I24: AULA VIRTUAL | J24: =IFERROR(VLOOKUP(K24,Docentes_Lista!$A$2:$C$212,2,FALSE),"") -> 0 | L24: =IFERROR(VLOOKUP(K24,Docentes_Lista!$A$2:$C$212,3,FALSE),"") -> 0
A25: 24 | B25: DES | C25: ESPRO-V | D25: Estándares De Programación | E25: 01 | F25: 00:00-23:59 | H25: Do-Ju-Lu-Ma-Mi-Sa-Vi | I25: AULA VIRTUAL | J25: =IFERROR(VLOOKUP(K25,Docentes_Lista!$A$2:$C$212,2,FALSE),"") -> 0 | L25: =IFERROR(VLOOKUP(K25,Docentes_Lista!$A$2:$C$212,3,FALSE),"") -> 0
A26: 25 | B26: DES | C26: ETPS1-V | D26: Técnicas De Producción Industrial De Software I | E26: 01 | F26: 00:00-23:59 | H26: Do-Ju-Lu-Ma-Mi-Sa-Vi | I26: AULA VIRTUAL | J26: =IFERROR(VLOOKUP(K26,Docentes_Lista!$A$2:$C$212,2,FALSE),"") -> 0 | L26: =IFERROR(VLOOKUP(K26,Docentes_Lista!$A$2:$C$212,3,FALSE),"") -> 0
A27: 26 | B27: DES | C27: ETPS2-V | D27: Técnicas De Producción Industrial De Software II | E27: 01 | F27: 00:00-23:59 | H27: Do-Ju-Lu-Ma-Mi-Sa-Vi | I27: AULA VIRTUAL | J27: =IFERROR(VLOOKUP(K27,Docentes_Lista!$A$2:$C$212,2,FALSE),"") -> 0 | L27: =IFERROR(VLOOKUP(K27,Docentes_Lista!$A$2:$C$212,3,FALSE),"") -> 0
A28: 27 | B28: DES | C28: ETPS3-T | D28: Técnicas De Calidad De Software | E28: 01 | F28: 06:30-08:00 | G28: 90 min | H28: Lu-Vi | I28: PRESENCIAL | J28: =IFERROR(VLOOKUP(K28,Docentes_Lista!$A$2:$C$212,2,FALSE),"") -> 0 | L28: =IFERROR(VLOOKUP(K28,Docentes_Lista!$A$2:$C$212,3,FALSE),"") -> 0
A29: 28 | B29: DES | C29: ETPS3-V | D29: Técnicas De Calidad De Software | E29: 01 | F29: 00:00-23:59 | H29: Do-Ju-Lu-Ma-Mi-Sa-Vi | I29: AULA VIRTUAL | J29: =IFERROR(VLOOKUP(K29,Docentes_Lista!$A$2:$C$212,2,FALSE),"") -> 0 | L29: =IFERROR(VLOOKUP(K29,Docentes_Lista!$A$2:$C$212,3,FALSE),"") -> 0
A30: 29 | B30: DES | C30: ETPS4-V | D30: Normas Y Estándares Internacionales | E30: 01 | F30: 00:00-23:59 | H30: Do-Ju-Lu-Ma-Mi-Sa-Vi | I30: AULA VIRTUAL | J30: =IFERROR(VLOOKUP(K30,Docentes_Lista!$A$2:$C$212,2,FALSE),"") -> 0 | L30: =IFERROR(VLOOKUP(K30,Docentes_Lista!$A$2:$C$212,3,FALSE),"") -> 0
A31: 30 | B31: RED | C31: ETS1-V | D31: Desarrollo De Redes De Datos I (et1) (virtual) | E31: 01 | F31: 00:00-23:59 | H31: Do-Ju-Lu-Ma-Mi-Sa-Vi | I31: AULA VIRTUAL | J31: =IFERROR(VLOOKUP(K31,Docentes_Lista!$A$2:$C$212,2,FALSE),"") -> 0 | L31: =IFERROR(VLOOKUP(K31,Docentes_Lista!$A$2:$C$212,3,FALSE),"") -> 0
A32: 31 | B32: RED | C32: ETS2-V | D32: Desarrollo De Redes De Datos II (et2) (virtual) | E32: 01 | F32: 00:00-23:59 | H32: Do-Ju-Lu-Ma-Mi-Sa-Vi | I32: AULA VIRTUAL | J32: =IFERROR(VLOOKUP(K32,Docentes_Lista!$A$2:$C$212,2,FALSE),"") -> 0 | L32: =IFERROR(VLOOKUP(K32,Docentes_Lista!$A$2:$C$212,3,FALSE),"") -> 0
A33: 32 | B33: RED | C33: ETS3-T | D33: Desarrollo De Redes De Datos III | E33: 01 | F33: 06:30-08:00 | G33: 90 min | H33: Lu-Vi | I33: PRESENCIAL | J33: =IFERROR(VLOOKUP(K33,Docentes_Lista!$A$2:$C$212,2,FALSE),"") -> 0 | L33: =IFERROR(VLOOKUP(K33,Docentes_Lista!$A$2:$C$212,3,FALSE),"") -> 0
A34: 33 | B34: RED | C34: ETS3-V | D34: Desarrollo De Redes De Datos III (et3) (virtual) | E34: 01 | F34: 00:00-23:59 | H34: Do-Ju-Lu-Ma-Mi-Sa-Vi | I34: AULA VIRTUAL | J34: =IFERROR(VLOOKUP(K34,Docentes_Lista!$A$2:$C$212,2,FALSE),"") -> 0 | L34: =IFERROR(VLOOKUP(K34,Docentes_Lista!$A$2:$C$212,3,FALSE),"") -> 0
A35: 34 | B35: RED | C35: ETS4-V | D35: Desarrollo De Redes De Datos IV (et4) (virtual) | E35: 01 | F35: 00:00-23:59 | H35: Do-Ju-Lu-Ma-Mi-Sa-Vi | I35: AULA VIRTUAL | J35: =IFERROR(VLOOKUP(K35,Docentes_Lista!$A$2:$C$212,2,FALSE),"") -> 0 | L35: =IFERROR(VLOOKUP(K35,Docentes_Lista!$A$2:$C$212,3,FALSE),"") -> 0
A36: 35 | B36: ELE | C36: IACI-I | D36: Introducción Al Análisis De Circuitos | E36: 01 | F36: 06:30-08:00 | G36: 90 min | H36: Lu-Vi | I36: PRESENCIAL | J36: =IFERROR(VLOOKUP(K36,Docentes_Lista!$A$2:$C$212,2,FALSE),"") -> 0 | L36: =IFERROR(VLOOKUP(K36,Docentes_Lista!$A$2:$C$212,3,FALSE),"") -> 0
A37: 36 | B37: ELE | C37: IACI-I | D37: Introducción Al Análisis De Circuitos | E37: 02 | F37: 10:00-13:00 | G37: 180 min | H37: Do | I37: PRESENCIAL | J37: =IFERROR(VLOOKUP(K37,Docentes_Lista!$A$2:$C$212,2,FALSE),"") -> 0 | L37: =IFERROR(VLOOKUP(K37,Docentes_Lista!$A$2:$C$212,3,FALSE),"") -> 0
A38: 37 | B38: ELE | C38: IACI-V | D38: Introducción Al Análisis De Circuitos (virtual) | E38: 01 | F38: 00:00-23:59 | H38: Do-Ju-Lu-Ma-Mi-Sa-Vi | I38: AULA VIRTUAL | J38: =IFERROR(VLOOKUP(K38,Docentes_Lista!$A$2:$C$212,2,FALSE),"") -> 0 | L38: =IFERROR(VLOOKUP(K38,Docentes_Lista!$A$2:$C$212,3,FALSE),"") -> 0
A39: 38 | B39: ELE | C39: INER-T | D39: Instalaciones Eléctricas Residenciales | E39: 01 | F39: 18:40-20:10 | G39: 90 min | H39: Lu-Mi | I39: EN LÍNEA | J39: =IFERROR(VLOOKUP(K39,Docentes_Lista!$A$2:$C$212,2,FALSE),"") -> 0 | L39: =IFERROR(VLOOKUP(K39,Docentes_Lista!$A$2:$C$212,3,FALSE),"") -> 0
A40: 39 | B40: RED | C40: INF1-I | D40: Informática | E40: 01 | F40: 06:30-08:00 | G40: 90 min | H40: Lu-Vi | I40: EN LÍNEA | J40: =IFERROR(VLOOKUP(K40,Docentes_Lista!$A$2:$C$212,2,FALSE),"") -> 0 | L40: =IFERROR(VLOOKUP(K40,Docentes_Lista!$A$2:$C$212,3,FALSE),"") -> 0
...

Sheet Docentes_Lista
A1: DOCENTE (Clave) | B1: TITULO | C1: ID_DOCENTE
A2: Adalberto Cortez Portillo | B2: Ing. | C2: 1
A3: Adolfo José Araujo Jaimes | B3: Ing. | C3: 2
A4: Aldo Rene Guevara Ramos | B4: Ing. | C4: 3
A5: Alfredo Omar Rodriguez Torres | B5: Ing. | C5: 4
A6: Alicia Del Carmen Martinez De Lopez | B6: Lda. | C6: 5
A7: Amílcar Alfredo Chavarria Cruz | B7: Ing. | C7: 7
A8: Ana Carolina Aguilar De Ramírez | B8: Lda. | C8: 9
A9: Ana Cecilia De Ramirez | B9: Lda. | C9: 8
A10: Ana Elizabeth Villalta Lopez | B10: Lda. | C10: 10
A11: Ana Marcela Argueta Meléndez | B11: Lda. | C11: 11
A12: Ana María Alvarado De Aguilar | B12: Lda. | C12: 12
A13: Ana Patricia Vásquez Cruz | B13: Arq. | C13: 13
... A212: Óscar Geovanni Álvarez Carlos | B212: Arq. | C212: 169
